<?xml version="1.0"?>
<robot xmlns:xacro="http://www.ros.org/wiki/xacro">

            <!-- Farben -->

    <material name="white">
        <color rgba="1 1 1 1"/>
    </material>

    <material name="black">
        <color rgba="0 0 0 1"/>
    </material>

    <material name="blue">
        <color rgba="0.2 0.2 1 1"/>
    </material>

    <material name="yellow">
        <color rgba="1 1 0 1"/>
    </material>

    <material name="orange">
        <color rgba="1 0.3 0.1 1"/>
    </material>

    <!-- BASE LINK -->

    <link name="base_link">
        
    </link>
    <!-- CHASSIS LINK -->
    <joint name="cassis_joint" type="fixed">
        <parent link="base_link"/>
        <child link="chassis"/>
        <origin xyz="-0.1 0.0 0.0"/>
        
    </joint>


    <link name="chassis">
        <visual>
            <origin xyz="0.15 0.0 0.075"/>
            <geometry>
                <box size="0.3 0.3 0.15"/>
            </geometry>
            <material name="black"/>
        </visual>
    </link>

        <!-- LEFT WHEEL LINK -->

    <joint name="left_wheel_joint" type="continuous">
        <origin xyz="0.0 0.0 0.0" rpy="0.0 0.0 0.0"/>
        <parent link="parent_link"/>
        <child link="child_link"/>
        <axis xyz="0.0 0.0 0.0"/>
        <limit lower="0.0" upper="0.0" effort="0.0" velocity="0.0"/>
    </joint>

    <link name="left_wheel">
        <visual>
            <geometry>
                <cylinder radius="0.05" length="0.04"/>
            </geometry>
            <material name="blue"/>               
        </visual>
    </link>





        <!-- RIGHT WHEEL LINK -->


    <!-- Body Part

    <link name="body">
        <visual>
            <geometry>
                <cylinder radius="0.11" length="0.345"/>
            </geometry>
            <material name="yellow">
            </material>
        </visual>        
    </link>

    <joint name="body_joint" type="fixed">
        <parent link="chassis"/>
        <child link="body"/>
        <origin xyz="0.0 0.0 0.17"/>        
    </joint>
-->
</robot>